2025-04-20 19:46:01,392 - __main__ - INFO - Initialized ModelIntegrator with anomaly model at http://localhost:8000
2025-04-20 19:46:01,392 - __main__ - INFO - Requesting anomaly prediction for 2023-05
2025-04-20 19:46:01,413 - __main__ - ERROR - Error getting anomaly prediction: HTTPConnectionPool(host='localhost', port=8000): Max retries exceeded with url: /predict_simple (Caused by NewConnectionError('<urllib3.connection.HTTPConnection object at 0x106ffada0>: Failed to establish a new connection: [Errno 61] Connection refused'))
Traceback (most recent call last):
  File "/Users/daiwikpal/.pyenv/versions/3.10.3/lib/python3.10/site-packages/urllib3/connection.py", line 198, in _new_conn
    sock = connection.create_connection(
  File "/Users/daiwikpal/.pyenv/versions/3.10.3/lib/python3.10/site-packages/urllib3/util/connection.py", line 85, in create_connection
    raise err
  File "/Users/daiwikpal/.pyenv/versions/3.10.3/lib/python3.10/site-packages/urllib3/util/connection.py", line 73, in create_connection
    sock.connect(sa)
ConnectionRefusedError: [Errno 61] Connection refused

The above exception was the direct cause of the following exception:

Traceback (most recent call last):
  File "/Users/daiwikpal/.pyenv/versions/3.10.3/lib/python3.10/site-packages/urllib3/connectionpool.py", line 787, in urlopen
    response = self._make_request(
  File "/Users/daiwikpal/.pyenv/versions/3.10.3/lib/python3.10/site-packages/urllib3/connectionpool.py", line 493, in _make_request
    conn.request(
  File "/Users/daiwikpal/.pyenv/versions/3.10.3/lib/python3.10/site-packages/urllib3/connection.py", line 445, in request
    self.endheaders()
  File "/Users/daiwikpal/.pyenv/versions/3.10.3/lib/python3.10/http/client.py", line 1277, in endheaders
    self._send_output(message_body, encode_chunked=encode_chunked)
  File "/Users/daiwikpal/.pyenv/versions/3.10.3/lib/python3.10/http/client.py", line 1037, in _send_output
    self.send(msg)
  File "/Users/daiwikpal/.pyenv/versions/3.10.3/lib/python3.10/http/client.py", line 975, in send
    self.connect()
  File "/Users/daiwikpal/.pyenv/versions/3.10.3/lib/python3.10/site-packages/urllib3/connection.py", line 276, in connect
    self.sock = self._new_conn()
  File "/Users/daiwikpal/.pyenv/versions/3.10.3/lib/python3.10/site-packages/urllib3/connection.py", line 213, in _new_conn
    raise NewConnectionError(
urllib3.exceptions.NewConnectionError: <urllib3.connection.HTTPConnection object at 0x106ffada0>: Failed to establish a new connection: [Errno 61] Connection refused

The above exception was the direct cause of the following exception:

Traceback (most recent call last):
  File "/Users/daiwikpal/.pyenv/versions/3.10.3/lib/python3.10/site-packages/requests/adapters.py", line 486, in send
    resp = conn.urlopen(
  File "/Users/daiwikpal/.pyenv/versions/3.10.3/lib/python3.10/site-packages/urllib3/connectionpool.py", line 841, in urlopen
    retries = retries.increment(
  File "/Users/daiwikpal/.pyenv/versions/3.10.3/lib/python3.10/site-packages/urllib3/util/retry.py", line 519, in increment
    raise MaxRetryError(_pool, url, reason) from reason  # type: ignore[arg-type]
urllib3.exceptions.MaxRetryError: HTTPConnectionPool(host='localhost', port=8000): Max retries exceeded with url: /predict_simple (Caused by NewConnectionError('<urllib3.connection.HTTPConnection object at 0x106ffada0>: Failed to establish a new connection: [Errno 61] Connection refused'))

During handling of the above exception, another exception occurred:

Traceback (most recent call last):
  File "/Users/daiwikpal/VSCode/ReTune/Integration_layer/model_integration.py", line 47, in get_anomaly_prediction
    response = requests.post(endpoint, json=payload)
  File "/Users/daiwikpal/.pyenv/versions/3.10.3/lib/python3.10/site-packages/requests/api.py", line 115, in post
    return request("post", url, data=data, json=json, **kwargs)
  File "/Users/daiwikpal/.pyenv/versions/3.10.3/lib/python3.10/site-packages/requests/api.py", line 59, in request
    return session.request(method=method, url=url, **kwargs)
  File "/Users/daiwikpal/.pyenv/versions/3.10.3/lib/python3.10/site-packages/requests/sessions.py", line 589, in request
    resp = self.send(prep, **send_kwargs)
  File "/Users/daiwikpal/.pyenv/versions/3.10.3/lib/python3.10/site-packages/requests/sessions.py", line 703, in send
    r = adapter.send(request, **kwargs)
  File "/Users/daiwikpal/.pyenv/versions/3.10.3/lib/python3.10/site-packages/requests/adapters.py", line 519, in send
    raise ConnectionError(e, request=request)
requests.exceptions.ConnectionError: HTTPConnectionPool(host='localhost', port=8000): Max retries exceeded with url: /predict_simple (Caused by NewConnectionError('<urllib3.connection.HTTPConnection object at 0x106ffada0>: Failed to establish a new connection: [Errno 61] Connection refused'))
2025-04-20 19:46:01,421 - __main__ - INFO - Requesting anomaly prediction for 2023-05
2025-04-20 19:46:01,427 - __main__ - ERROR - Error getting anomaly prediction: HTTPConnectionPool(host='localhost', port=8000): Max retries exceeded with url: /predict_simple (Caused by NewConnectionError('<urllib3.connection.HTTPConnection object at 0x106ffbac0>: Failed to establish a new connection: [Errno 61] Connection refused'))
Traceback (most recent call last):
  File "/Users/daiwikpal/.pyenv/versions/3.10.3/lib/python3.10/site-packages/urllib3/connection.py", line 198, in _new_conn
    sock = connection.create_connection(
  File "/Users/daiwikpal/.pyenv/versions/3.10.3/lib/python3.10/site-packages/urllib3/util/connection.py", line 85, in create_connection
    raise err
  File "/Users/daiwikpal/.pyenv/versions/3.10.3/lib/python3.10/site-packages/urllib3/util/connection.py", line 73, in create_connection
    sock.connect(sa)
ConnectionRefusedError: [Errno 61] Connection refused

The above exception was the direct cause of the following exception:

Traceback (most recent call last):
  File "/Users/daiwikpal/.pyenv/versions/3.10.3/lib/python3.10/site-packages/urllib3/connectionpool.py", line 787, in urlopen
    response = self._make_request(
  File "/Users/daiwikpal/.pyenv/versions/3.10.3/lib/python3.10/site-packages/urllib3/connectionpool.py", line 493, in _make_request
    conn.request(
  File "/Users/daiwikpal/.pyenv/versions/3.10.3/lib/python3.10/site-packages/urllib3/connection.py", line 445, in request
    self.endheaders()
  File "/Users/daiwikpal/.pyenv/versions/3.10.3/lib/python3.10/http/client.py", line 1277, in endheaders
    self._send_output(message_body, encode_chunked=encode_chunked)
  File "/Users/daiwikpal/.pyenv/versions/3.10.3/lib/python3.10/http/client.py", line 1037, in _send_output
    self.send(msg)
  File "/Users/daiwikpal/.pyenv/versions/3.10.3/lib/python3.10/http/client.py", line 975, in send
    self.connect()
  File "/Users/daiwikpal/.pyenv/versions/3.10.3/lib/python3.10/site-packages/urllib3/connection.py", line 276, in connect
    self.sock = self._new_conn()
  File "/Users/daiwikpal/.pyenv/versions/3.10.3/lib/python3.10/site-packages/urllib3/connection.py", line 213, in _new_conn
    raise NewConnectionError(
urllib3.exceptions.NewConnectionError: <urllib3.connection.HTTPConnection object at 0x106ffbac0>: Failed to establish a new connection: [Errno 61] Connection refused

The above exception was the direct cause of the following exception:

Traceback (most recent call last):
  File "/Users/daiwikpal/.pyenv/versions/3.10.3/lib/python3.10/site-packages/requests/adapters.py", line 486, in send
    resp = conn.urlopen(
  File "/Users/daiwikpal/.pyenv/versions/3.10.3/lib/python3.10/site-packages/urllib3/connectionpool.py", line 841, in urlopen
    retries = retries.increment(
  File "/Users/daiwikpal/.pyenv/versions/3.10.3/lib/python3.10/site-packages/urllib3/util/retry.py", line 519, in increment
    raise MaxRetryError(_pool, url, reason) from reason  # type: ignore[arg-type]
urllib3.exceptions.MaxRetryError: HTTPConnectionPool(host='localhost', port=8000): Max retries exceeded with url: /predict_simple (Caused by NewConnectionError('<urllib3.connection.HTTPConnection object at 0x106ffbac0>: Failed to establish a new connection: [Errno 61] Connection refused'))

During handling of the above exception, another exception occurred:

Traceback (most recent call last):
  File "/Users/daiwikpal/VSCode/ReTune/Integration_layer/model_integration.py", line 47, in get_anomaly_prediction
    response = requests.post(endpoint, json=payload)
  File "/Users/daiwikpal/.pyenv/versions/3.10.3/lib/python3.10/site-packages/requests/api.py", line 115, in post
    return request("post", url, data=data, json=json, **kwargs)
  File "/Users/daiwikpal/.pyenv/versions/3.10.3/lib/python3.10/site-packages/requests/api.py", line 59, in request
    return session.request(method=method, url=url, **kwargs)
  File "/Users/daiwikpal/.pyenv/versions/3.10.3/lib/python3.10/site-packages/requests/sessions.py", line 589, in request
    resp = self.send(prep, **send_kwargs)
  File "/Users/daiwikpal/.pyenv/versions/3.10.3/lib/python3.10/site-packages/requests/sessions.py", line 703, in send
    r = adapter.send(request, **kwargs)
  File "/Users/daiwikpal/.pyenv/versions/3.10.3/lib/python3.10/site-packages/requests/adapters.py", line 519, in send
    raise ConnectionError(e, request=request)
requests.exceptions.ConnectionError: HTTPConnectionPool(host='localhost', port=8000): Max retries exceeded with url: /predict_simple (Caused by NewConnectionError('<urllib3.connection.HTTPConnection object at 0x106ffbac0>: Failed to establish a new connection: [Errno 61] Connection refused'))
2025-04-20 19:46:38,834 - __main__ - INFO - Initialized ModelIntegrator with anomaly model at http://localhost:8000
2025-04-20 19:46:38,835 - __main__ - INFO - Requesting anomaly prediction for 2023-05
2025-04-20 19:46:39,860 - __main__ - INFO - Received anomaly prediction: 3.5210416316986084
2025-04-20 19:46:39,860 - __main__ - INFO - Requesting anomaly prediction for 2023-05
2025-04-20 19:46:40,848 - __main__ - INFO - Received anomaly prediction: 3.5210416316986084
2025-04-20 19:46:40,848 - __main__ - INFO - Combined prediction: 3.112624979019165 (weights: anomaly=0.6, precipitation=0.4)
2025-04-22 02:07:10,337 - __main__ - INFO - Initialized ModelIntegrator with anomaly model at http://localhost:8000
2025-04-22 02:07:10,337 - __main__ - INFO - Requesting anomaly prediction for 2023-05
2025-04-22 02:07:11,346 - __main__ - INFO - Received anomaly prediction: 3.5210416316986084
2025-04-22 02:07:11,346 - __main__ - INFO - Requesting precipitation prediction for 2023-05
2025-04-22 02:07:11,348 - __main__ - ERROR - Error getting precipitation prediction: HTTPConnectionPool(host='localhost', port=8001): Max retries exceeded with url: /predict (Caused by NewConnectionError('<urllib3.connection.HTTPConnection object at 0x104ed2d70>: Failed to establish a new connection: [Errno 61] Connection refused'))
Traceback (most recent call last):
  File "/Users/daiwikpal/.pyenv/versions/3.10.3/lib/python3.10/site-packages/urllib3/connection.py", line 198, in _new_conn
    sock = connection.create_connection(
  File "/Users/daiwikpal/.pyenv/versions/3.10.3/lib/python3.10/site-packages/urllib3/util/connection.py", line 85, in create_connection
    raise err
  File "/Users/daiwikpal/.pyenv/versions/3.10.3/lib/python3.10/site-packages/urllib3/util/connection.py", line 73, in create_connection
    sock.connect(sa)
ConnectionRefusedError: [Errno 61] Connection refused

The above exception was the direct cause of the following exception:

Traceback (most recent call last):
  File "/Users/daiwikpal/.pyenv/versions/3.10.3/lib/python3.10/site-packages/urllib3/connectionpool.py", line 787, in urlopen
    response = self._make_request(
  File "/Users/daiwikpal/.pyenv/versions/3.10.3/lib/python3.10/site-packages/urllib3/connectionpool.py", line 493, in _make_request
    conn.request(
  File "/Users/daiwikpal/.pyenv/versions/3.10.3/lib/python3.10/site-packages/urllib3/connection.py", line 445, in request
    self.endheaders()
  File "/Users/daiwikpal/.pyenv/versions/3.10.3/lib/python3.10/http/client.py", line 1277, in endheaders
    self._send_output(message_body, encode_chunked=encode_chunked)
  File "/Users/daiwikpal/.pyenv/versions/3.10.3/lib/python3.10/http/client.py", line 1037, in _send_output
    self.send(msg)
  File "/Users/daiwikpal/.pyenv/versions/3.10.3/lib/python3.10/http/client.py", line 975, in send
    self.connect()
  File "/Users/daiwikpal/.pyenv/versions/3.10.3/lib/python3.10/site-packages/urllib3/connection.py", line 276, in connect
    self.sock = self._new_conn()
  File "/Users/daiwikpal/.pyenv/versions/3.10.3/lib/python3.10/site-packages/urllib3/connection.py", line 213, in _new_conn
    raise NewConnectionError(
urllib3.exceptions.NewConnectionError: <urllib3.connection.HTTPConnection object at 0x104ed2d70>: Failed to establish a new connection: [Errno 61] Connection refused

The above exception was the direct cause of the following exception:

Traceback (most recent call last):
  File "/Users/daiwikpal/.pyenv/versions/3.10.3/lib/python3.10/site-packages/requests/adapters.py", line 486, in send
    resp = conn.urlopen(
  File "/Users/daiwikpal/.pyenv/versions/3.10.3/lib/python3.10/site-packages/urllib3/connectionpool.py", line 841, in urlopen
    retries = retries.increment(
  File "/Users/daiwikpal/.pyenv/versions/3.10.3/lib/python3.10/site-packages/urllib3/util/retry.py", line 519, in increment
    raise MaxRetryError(_pool, url, reason) from reason  # type: ignore[arg-type]
urllib3.exceptions.MaxRetryError: HTTPConnectionPool(host='localhost', port=8001): Max retries exceeded with url: /predict (Caused by NewConnectionError('<urllib3.connection.HTTPConnection object at 0x104ed2d70>: Failed to establish a new connection: [Errno 61] Connection refused'))

During handling of the above exception, another exception occurred:

Traceback (most recent call last):
  File "/Users/daiwikpal/VSCode/ReTune/Integration_layer/model_integration.py", line 75, in get_precipitation_prediction
    response = requests.post(endpoint, json=payload)
  File "/Users/daiwikpal/.pyenv/versions/3.10.3/lib/python3.10/site-packages/requests/api.py", line 115, in post
    return request("post", url, data=data, json=json, **kwargs)
  File "/Users/daiwikpal/.pyenv/versions/3.10.3/lib/python3.10/site-packages/requests/api.py", line 59, in request
    return session.request(method=method, url=url, **kwargs)
  File "/Users/daiwikpal/.pyenv/versions/3.10.3/lib/python3.10/site-packages/requests/sessions.py", line 589, in request
    resp = self.send(prep, **send_kwargs)
  File "/Users/daiwikpal/.pyenv/versions/3.10.3/lib/python3.10/site-packages/requests/sessions.py", line 703, in send
    r = adapter.send(request, **kwargs)
  File "/Users/daiwikpal/.pyenv/versions/3.10.3/lib/python3.10/site-packages/requests/adapters.py", line 519, in send
    raise ConnectionError(e, request=request)
requests.exceptions.ConnectionError: HTTPConnectionPool(host='localhost', port=8001): Max retries exceeded with url: /predict (Caused by NewConnectionError('<urllib3.connection.HTTPConnection object at 0x104ed2d70>: Failed to establish a new connection: [Errno 61] Connection refused'))
2025-04-22 02:07:11,353 - __main__ - INFO - Requesting anomaly prediction for 2023-05
2025-04-22 02:07:12,115 - __main__ - INFO - Received anomaly prediction: 3.5210416316986084
2025-04-22 02:07:12,115 - __main__ - INFO - Requesting precipitation prediction for 2023-05
2025-04-22 02:07:12,117 - __main__ - ERROR - Error getting precipitation prediction: HTTPConnectionPool(host='localhost', port=8001): Max retries exceeded with url: /predict (Caused by NewConnectionError('<urllib3.connection.HTTPConnection object at 0x104ed2b60>: Failed to establish a new connection: [Errno 61] Connection refused'))
Traceback (most recent call last):
  File "/Users/daiwikpal/.pyenv/versions/3.10.3/lib/python3.10/site-packages/urllib3/connection.py", line 198, in _new_conn
    sock = connection.create_connection(
  File "/Users/daiwikpal/.pyenv/versions/3.10.3/lib/python3.10/site-packages/urllib3/util/connection.py", line 85, in create_connection
    raise err
  File "/Users/daiwikpal/.pyenv/versions/3.10.3/lib/python3.10/site-packages/urllib3/util/connection.py", line 73, in create_connection
    sock.connect(sa)
ConnectionRefusedError: [Errno 61] Connection refused

The above exception was the direct cause of the following exception:

Traceback (most recent call last):
  File "/Users/daiwikpal/.pyenv/versions/3.10.3/lib/python3.10/site-packages/urllib3/connectionpool.py", line 787, in urlopen
    response = self._make_request(
  File "/Users/daiwikpal/.pyenv/versions/3.10.3/lib/python3.10/site-packages/urllib3/connectionpool.py", line 493, in _make_request
    conn.request(
  File "/Users/daiwikpal/.pyenv/versions/3.10.3/lib/python3.10/site-packages/urllib3/connection.py", line 445, in request
    self.endheaders()
  File "/Users/daiwikpal/.pyenv/versions/3.10.3/lib/python3.10/http/client.py", line 1277, in endheaders
    self._send_output(message_body, encode_chunked=encode_chunked)
  File "/Users/daiwikpal/.pyenv/versions/3.10.3/lib/python3.10/http/client.py", line 1037, in _send_output
    self.send(msg)
  File "/Users/daiwikpal/.pyenv/versions/3.10.3/lib/python3.10/http/client.py", line 975, in send
    self.connect()
  File "/Users/daiwikpal/.pyenv/versions/3.10.3/lib/python3.10/site-packages/urllib3/connection.py", line 276, in connect
    self.sock = self._new_conn()
  File "/Users/daiwikpal/.pyenv/versions/3.10.3/lib/python3.10/site-packages/urllib3/connection.py", line 213, in _new_conn
    raise NewConnectionError(
urllib3.exceptions.NewConnectionError: <urllib3.connection.HTTPConnection object at 0x104ed2b60>: Failed to establish a new connection: [Errno 61] Connection refused

The above exception was the direct cause of the following exception:

Traceback (most recent call last):
  File "/Users/daiwikpal/.pyenv/versions/3.10.3/lib/python3.10/site-packages/requests/adapters.py", line 486, in send
    resp = conn.urlopen(
  File "/Users/daiwikpal/.pyenv/versions/3.10.3/lib/python3.10/site-packages/urllib3/connectionpool.py", line 841, in urlopen
    retries = retries.increment(
  File "/Users/daiwikpal/.pyenv/versions/3.10.3/lib/python3.10/site-packages/urllib3/util/retry.py", line 519, in increment
    raise MaxRetryError(_pool, url, reason) from reason  # type: ignore[arg-type]
urllib3.exceptions.MaxRetryError: HTTPConnectionPool(host='localhost', port=8001): Max retries exceeded with url: /predict (Caused by NewConnectionError('<urllib3.connection.HTTPConnection object at 0x104ed2b60>: Failed to establish a new connection: [Errno 61] Connection refused'))

During handling of the above exception, another exception occurred:

Traceback (most recent call last):
  File "/Users/daiwikpal/VSCode/ReTune/Integration_layer/model_integration.py", line 75, in get_precipitation_prediction
    response = requests.post(endpoint, json=payload)
  File "/Users/daiwikpal/.pyenv/versions/3.10.3/lib/python3.10/site-packages/requests/api.py", line 115, in post
    return request("post", url, data=data, json=json, **kwargs)
  File "/Users/daiwikpal/.pyenv/versions/3.10.3/lib/python3.10/site-packages/requests/api.py", line 59, in request
    return session.request(method=method, url=url, **kwargs)
  File "/Users/daiwikpal/.pyenv/versions/3.10.3/lib/python3.10/site-packages/requests/sessions.py", line 589, in request
    resp = self.send(prep, **send_kwargs)
  File "/Users/daiwikpal/.pyenv/versions/3.10.3/lib/python3.10/site-packages/requests/sessions.py", line 703, in send
    r = adapter.send(request, **kwargs)
  File "/Users/daiwikpal/.pyenv/versions/3.10.3/lib/python3.10/site-packages/requests/adapters.py", line 519, in send
    raise ConnectionError(e, request=request)
requests.exceptions.ConnectionError: HTTPConnectionPool(host='localhost', port=8001): Max retries exceeded with url: /predict (Caused by NewConnectionError('<urllib3.connection.HTTPConnection object at 0x104ed2b60>: Failed to establish a new connection: [Errno 61] Connection refused'))
2025-04-22 02:10:41,946 - __main__ - INFO - Initialized ModelIntegrator with anomaly model at http://localhost:8000
2025-04-22 02:10:41,947 - __main__ - INFO - Requesting anomaly prediction for 2023-05
2025-04-22 02:10:43,306 - __main__ - INFO - Received anomaly prediction: 3.5210416316986084
2025-04-22 02:10:43,306 - __main__ - INFO - Requesting precipitation prediction for 2023-05
2025-04-22 02:10:44,000 - __main__ - INFO - Received precipitation prediction: 2.9915
2025-04-22 02:10:44,000 - __main__ - INFO - Combined prediction: 3.2562708158493043 (weights: anomaly=0.5, precipitation=0.5)
2025-04-22 02:10:44,001 - __main__ - INFO - Requesting anomaly prediction for 2023-05
2025-04-22 02:10:44,561 - __main__ - INFO - Received anomaly prediction: 3.5210416316986084
2025-04-22 02:10:44,561 - __main__ - INFO - Requesting precipitation prediction for 2023-05
2025-04-22 02:10:44,605 - __main__ - INFO - Received precipitation prediction: 2.9915
2025-04-22 02:10:44,605 - __main__ - INFO - Combined prediction: 3.309224979019165 (weights: anomaly=0.6, precipitation=0.4)
